"Traceback (most recent call last):\n  File \"/home/runner/workspace/.pythonlibs/bin/uvicorn\", line 8, in <module>\n    sys.exit(main())\n             ^^^^^^\n  File \"/home/runner/workspace/.pythonlibs/lib/python3.12/site-packages/click/core.py\", line 1442, in __call__\n    return self.main(*args, **kwargs)\n           ^^^^^^^^^^^^^^^^^^^^^^^^^^\n  File \"/home/runner/workspace/.pythonlibs/lib/python3.12/site-packages/click/core.py\", line 1363, in main\n    rv = self.invoke(ctx)\n         ^^^^^^^^^^^^^^^^\n  File \"/home/runner/workspace/.pythonlibs/lib/python3.12/site-packages/click/core.py\", line 1226, in invoke\n    return ctx.invoke(self.callback, **ctx.params)\n           ^^^^^^^^^^^^^^^^^^^^^^^^^^^^^^^^^^^^^^^\n  File \"/home/runner/workspace/.pythonlibs/lib/python3.12/site-packages/click/core.py\", line 794, in invoke\n    return callback(*args, **kwargs)\n           ^^^^^^^^^^^^^^^^^^^^^^^^^\n  File \"/home/runner/workspace/.pythonlibs/lib/python3.12/site-packages/uvicorn/main.py\", line 413, in main\n    run(\n  File \"/home/runner/workspace/.pythonlibs/lib/python3.12/site-packages/uvicorn/main.py\", line 580, in run\n    server.run()\n  File \"/home/runner/workspace/.pythonlibs/lib/python3.12/site-packages/uvicorn/server.py\", line 67, in run\n    return asyncio.run(self.serve(sockets=sockets))\n           ^^^^^^^^^^^^^^^^^^^^^^^^^^^^^^^^^^^^^^^^\n  File \"/nix/store/nb21sc3npfc8gvazwnrjxpvb5d48jysx-python3-3.12.7/lib/python3.12/asyncio/runners.py\", line 194, in run\n    return runner.run(main)\n           ^^^^^^^^^^^^^^^^\n  File \"/nix/store/nb21sc3npfc8gvazwnrjxpvb5d48jysx-python3-3.12.7/lib/python3.12/asyncio/runners.py\", line 118, in run\n    return self._loop.run_until_complete(task)\n           ^^^^^^^^^^^^^^^^^^^^^^^^^^^^^^^^^^^\n  File \"uvloop/loop.pyx\", line 1518, in uvloop.loop.Loop.run_until_complete\n  File \"/home/runner/workspace/.pythonlibs/lib/python3.12/site-packages/uvicorn/server.py\", line 71, in serve\n    await self._serve(sockets)\n  File \"/home/runner/workspace/.pythonlibs/lib/python3.12/site-packages/uvicorn/server.py\", line 78, in _serve\n    config.load()\n  File \"/home/runner/workspace/.pythonlibs/lib/python3.12/site-packages/uvicorn/config.py\", line 436, in load\n    self.loaded_app = import_from_string(self.app)\n                      ^^^^^^^^^^^^^^^^^^^^^^^^^^^^\n  File \"/home/runner/workspace/.pythonlibs/lib/python3.12/site-packages/uvicorn/importer.py\", line 19, in import_from_string\n    module = importlib.import_module(module_str)\n             ^^^^^^^^^^^^^^^^^^^^^^^^^^^^^^^^^^^\n  File \"/nix/store/nb21sc3npfc8gvazwnrjxpvb5d48jysx-python3-3.12.7/lib/python3.12/importlib/__init__.py\", line 90, in import_module\n    return _bootstrap._gcd_import(name[level:], package, level)\n           ^^^^^^^^^^^^^^^^^^^^^^^^^^^^^^^^^^^^^^^^^^^^^^^^^^^^\n  File \"<frozen importlib._bootstrap>\", line 1387, in _gcd_import\n  File \"<frozen importlib._bootstrap>\", line 1360, in _find_and_load\n  File \"<frozen importlib._bootstrap>\", line 1331, in _find_and_load_unlocked\n  File \"<frozen importlib._bootstrap>\", line 935, in _load_unlocked\n  File \"<frozen importlib._bootstrap_external>\", line 995, in exec_module\n  File \"<frozen importlib._bootstrap>\", line 488, in _call_with_frames_removed\n  File \"/home/runner/workspace/main.py\", line 13, in <module>\n    from app.main import main\n  File \"/home/runner/workspace/app/main.py\", line 14, in <module>\n    from app.config import settings\n  File \"/home/runner/workspace/app/config.py\", line 7, in <module>\n    from pydantic import BaseSettings\n  File \"/home/runner/workspace/.pythonlibs/lib/python3.12/site-packages/pydantic/__init__.py\", line 426, in __getattr__\n    return _getattr_migration(attr_name)\n           ^^^^^^^^^^^^^^^^^^^^^^^^^^^^^\n  File \"/home/runner/workspace/.pythonlibs/lib/python3.12/site-packages/pydantic/_migration.py\", line 296, in wrapper\n    raise PydanticImportError(\npydantic.errors.PydanticImportError: `BaseSettings` has been moved to the `pydantic-settings` package. See https://docs.pydantic.dev/2.11/migration/#basesettings-has-moved-to-pydantic-settings for more details.\n\nFor further information visit https://errors.pydantic.dev/2.11/u/import-error"

